*** Starting uWSGI 2.0.17 (64bit) on [Mon Jun  4 21:50:41 2018] ***
compiled with version: 4.2.1 Compatible Apple LLVM 8.0.0 (clang-800.0.42.1) on 05 June 2018 04:46:59
os: Darwin-16.4.0 Darwin Kernel Version 16.4.0: Thu Dec 22 22:53:21 PST 2016; root:xnu-3789.41.3~3/RELEASE_X86_64
nodename: jinxuanws-MacBook-Air.local
machine: x86_64
clock source: unix
pcre jit disabled
detected number of CPU cores: 4
current working directory: /Users/jinxuanwu/github/systems-puzzle
detected binary path: /Users/jinxuanwu/github/systems-puzzle/venv/bin/uwsgi
your processes number limit is 709
your memory page size is 4096 bytes
detected max file descriptor number: 10240
lock engine: OSX spinlocks
thunder lock: disabled (you can enable it with --thunder-lock)
uwsgi socket 0 bound to TCP address 0.0.0:5000 fd 3
Python version: 3.6.5 (default, Jun  4 2018, 18:56:20)  [GCC 4.2.1 Compatible Apple LLVM 8.0.0 (clang-800.0.42.1)]
Python main interpreter initialized at 0x7fa27a804a00
python threads support enabled
your server socket listen backlog is limited to 100 connections
your mercy for graceful operations on workers is 60 seconds
mapped 1694240 bytes (1654 KB) for 16 cores
*** Operational MODE: preforking+threaded ***
added /Users/jinxuanwu/github/systems-puzzle/ to pythonpath.
/Users/jinxuanwu/github/systems-puzzle/venv/lib/python3.6/site-packages/psycopg2/__init__.py:144: UserWarning: The psycopg2 wheel package will be renamed from release 2.8; in order to keep installing from binary please use "pip install psycopg2-binary" instead. For details see: <http://initd.org/psycopg/docs/install.html#binary-install-from-pypi>.
  """)
WSGI app 0 (mountpoint='') ready in 0 seconds on interpreter 0x7fa27a804a00 pid: 71903 (default app)
*** uWSGI is running in multiple interpreter mode ***
spawned uWSGI master process (pid: 71903)
spawned uWSGI worker 1 (pid: 71907, cores: 4)
spawned uWSGI worker 2 (pid: 71908, cores: 4)
spawned uWSGI worker 3 (pid: 71909, cores: 4)
spawned uWSGI worker 4 (pid: 71910, cores: 4)
[pid: 71909|app: 0|req: 1/1] 127.0.0.1 () {40 vars in 721 bytes} [Mon Jun  4 21:57:29 2018] GET / => generated 1057 bytes in 214 msecs (HTTP/1.1 200) 4 headers in 246 bytes (2 switches on core 3)
[pid: 71910|app: 0|req: 1/2] 127.0.0.1 () {42 vars in 834 bytes} [Mon Jun  4 21:57:29 2018] GET /favicon.ico => generated 233 bytes in 52 msecs (HTTP/1.1 404) 2 headers in 72 bytes (1 switches on core 3)
[pid: 71910|app: 0|req: 2/3] 127.0.0.1 () {52 vars in 1077 bytes} [Mon Jun  4 21:57:43 2018] POST / => generated 223 bytes in 81 msecs (HTTP/1.1 302) 4 headers in 138 bytes (1 switches on core 2)
[name: item1, quantity: 1, description: test, date_added: 2018-06-04 19:31:48.663470
, name: item2, quantity: 1, description: test2, date_added: 2018-06-04 19:49:13.775831
, name: item3, quantity: 1, description: test3, date_added: 2018-06-04 21:57:43.177801
]
[pid: 71910|app: 0|req: 3/4] 127.0.0.1 () {46 vars in 938 bytes} [Mon Jun  4 21:57:43 2018] GET /success => generated 260 bytes in 4 msecs (HTTP/1.1 200) 2 headers in 80 bytes (2 switches on core 0)
[pid: 71910|app: 0|req: 4/5] 127.0.0.1 () {42 vars in 855 bytes} [Mon Jun  4 21:57:48 2018] GET / => generated 1173 bytes in 65 msecs (HTTP/1.1 200) 3 headers in 95 bytes (1 switches on core 1)
[2018-06-04 23:15:50,713] ERROR in app: Exception on / [GET]
Traceback (most recent call last):
  File "/Users/jinxuanwu/github/systems-puzzle/venv/lib/python3.6/site-packages/sqlalchemy/engine/base.py", line 2158, in _wrap_pool_connect
    return fn()
  File "/Users/jinxuanwu/github/systems-puzzle/venv/lib/python3.6/site-packages/sqlalchemy/pool.py", line 403, in connect
    return _ConnectionFairy._checkout(self)
  File "/Users/jinxuanwu/github/systems-puzzle/venv/lib/python3.6/site-packages/sqlalchemy/pool.py", line 791, in _checkout
    fairy = _ConnectionRecord.checkout(pool)
  File "/Users/jinxuanwu/github/systems-puzzle/venv/lib/python3.6/site-packages/sqlalchemy/pool.py", line 532, in checkout
    rec = pool._do_get()
  File "/Users/jinxuanwu/github/systems-puzzle/venv/lib/python3.6/site-packages/sqlalchemy/pool.py", line 1196, in _do_get
    self._dec_overflow()
  File "/Users/jinxuanwu/github/systems-puzzle/venv/lib/python3.6/site-packages/sqlalchemy/util/langhelpers.py", line 66, in __exit__
    compat.reraise(exc_type, exc_value, exc_tb)
  File "/Users/jinxuanwu/github/systems-puzzle/venv/lib/python3.6/site-packages/sqlalchemy/util/compat.py", line 187, in reraise
    raise value
  File "/Users/jinxuanwu/github/systems-puzzle/venv/lib/python3.6/site-packages/sqlalchemy/pool.py", line 1193, in _do_get
    return self._create_connection()
  File "/Users/jinxuanwu/github/systems-puzzle/venv/lib/python3.6/site-packages/sqlalchemy/pool.py", line 350, in _create_connection
    return _ConnectionRecord(self)
  File "/Users/jinxuanwu/github/systems-puzzle/venv/lib/python3.6/site-packages/sqlalchemy/pool.py", line 477, in __init__
    self.__connect(first_connect_check=True)
  File "/Users/jinxuanwu/github/systems-puzzle/venv/lib/python3.6/site-packages/sqlalchemy/pool.py", line 674, in __connect
    connection = pool._invoke_creator(self)
  File "/Users/jinxuanwu/github/systems-puzzle/venv/lib/python3.6/site-packages/sqlalchemy/engine/strategies.py", line 106, in connect
    return dialect.connect(*cargs, **cparams)
  File "/Users/jinxuanwu/github/systems-puzzle/venv/lib/python3.6/site-packages/sqlalchemy/engine/default.py", line 411, in connect
    return self.dbapi.connect(*cargs, **cparams)
  File "/Users/jinxuanwu/github/systems-puzzle/venv/lib/python3.6/site-packages/psycopg2/__init__.py", line 130, in connect
    conn = _connect(dsn, connection_factory=connection_factory, **kwasync)
psycopg2.OperationalError: fe_sendauth: no password supplied


The above exception was the direct cause of the following exception:

Traceback (most recent call last):
  File "/Users/jinxuanwu/github/systems-puzzle/venv/lib/python3.6/site-packages/flask/app.py", line 2292, in wsgi_app
    response = self.full_dispatch_request()
  File "/Users/jinxuanwu/github/systems-puzzle/venv/lib/python3.6/site-packages/flask/app.py", line 1815, in full_dispatch_request
    rv = self.handle_user_exception(e)
  File "/Users/jinxuanwu/github/systems-puzzle/venv/lib/python3.6/site-packages/flask/app.py", line 1718, in handle_user_exception
    reraise(exc_type, exc_value, tb)
  File "/Users/jinxuanwu/github/systems-puzzle/venv/lib/python3.6/site-packages/flask/_compat.py", line 35, in reraise
    raise value
  File "/Users/jinxuanwu/github/systems-puzzle/venv/lib/python3.6/site-packages/flask/app.py", line 1813, in full_dispatch_request
    rv = self.dispatch_request()
  File "/Users/jinxuanwu/github/systems-puzzle/venv/lib/python3.6/site-packages/flask/app.py", line 1799, in dispatch_request
    return self.view_functions[rule.endpoint](**req.view_args)
  File "/Users/jinxuanwu/github/systems-puzzle/app.py", line 20, in add_item
    current_items=Items.query.all()
  File "/Users/jinxuanwu/github/systems-puzzle/venv/lib/python3.6/site-packages/sqlalchemy/orm/query.py", line 2783, in all
    return list(self)
  File "/Users/jinxuanwu/github/systems-puzzle/venv/lib/python3.6/site-packages/sqlalchemy/orm/query.py", line 2935, in __iter__
    return self._execute_and_instances(context)
  File "/Users/jinxuanwu/github/systems-puzzle/venv/lib/python3.6/site-packages/sqlalchemy/orm/query.py", line 2956, in _execute_and_instances
    close_with_result=True)
  File "/Users/jinxuanwu/github/systems-puzzle/venv/lib/python3.6/site-packages/sqlalchemy/orm/query.py", line 2965, in _get_bind_args
    **kw
  File "/Users/jinxuanwu/github/systems-puzzle/venv/lib/python3.6/site-packages/sqlalchemy/orm/query.py", line 2947, in _connection_from_session
    conn = self.session.connection(**kw)
  File "/Users/jinxuanwu/github/systems-puzzle/venv/lib/python3.6/site-packages/sqlalchemy/orm/session.py", line 1035, in connection
    execution_options=execution_options)
  File "/Users/jinxuanwu/github/systems-puzzle/venv/lib/python3.6/site-packages/sqlalchemy/orm/session.py", line 1040, in _connection_for_bind
    engine, execution_options)
  File "/Users/jinxuanwu/github/systems-puzzle/venv/lib/python3.6/site-packages/sqlalchemy/orm/session.py", line 409, in _connection_for_bind
    conn = bind.contextual_connect()
  File "/Users/jinxuanwu/github/systems-puzzle/venv/lib/python3.6/site-packages/sqlalchemy/engine/base.py", line 2123, in contextual_connect
    self._wrap_pool_connect(self.pool.connect, None),
  File "/Users/jinxuanwu/github/systems-puzzle/venv/lib/python3.6/site-packages/sqlalchemy/engine/base.py", line 2162, in _wrap_pool_connect
    e, dialect, self)
  File "/Users/jinxuanwu/github/systems-puzzle/venv/lib/python3.6/site-packages/sqlalchemy/engine/base.py", line 1476, in _handle_dbapi_exception_noconnection
    exc_info
  File "/Users/jinxuanwu/github/systems-puzzle/venv/lib/python3.6/site-packages/sqlalchemy/util/compat.py", line 203, in raise_from_cause
    reraise(type(exception), exception, tb=exc_tb, cause=cause)
  File "/Users/jinxuanwu/github/systems-puzzle/venv/lib/python3.6/site-packages/sqlalchemy/util/compat.py", line 186, in reraise
    raise value.with_traceback(tb)
  File "/Users/jinxuanwu/github/systems-puzzle/venv/lib/python3.6/site-packages/sqlalchemy/engine/base.py", line 2158, in _wrap_pool_connect
    return fn()
  File "/Users/jinxuanwu/github/systems-puzzle/venv/lib/python3.6/site-packages/sqlalchemy/pool.py", line 403, in connect
    return _ConnectionFairy._checkout(self)
  File "/Users/jinxuanwu/github/systems-puzzle/venv/lib/python3.6/site-packages/sqlalchemy/pool.py", line 791, in _checkout
    fairy = _ConnectionRecord.checkout(pool)
  File "/Users/jinxuanwu/github/systems-puzzle/venv/lib/python3.6/site-packages/sqlalchemy/pool.py", line 532, in checkout
    rec = pool._do_get()
  File "/Users/jinxuanwu/github/systems-puzzle/venv/lib/python3.6/site-packages/sqlalchemy/pool.py", line 1196, in _do_get
    self._dec_overflow()
  File "/Users/jinxuanwu/github/systems-puzzle/venv/lib/python3.6/site-packages/sqlalchemy/util/langhelpers.py", line 66, in __exit__
    compat.reraise(exc_type, exc_value, exc_tb)
  File "/Users/jinxuanwu/github/systems-puzzle/venv/lib/python3.6/site-packages/sqlalchemy/util/compat.py", line 187, in reraise
    raise value
  File "/Users/jinxuanwu/github/systems-puzzle/venv/lib/python3.6/site-packages/sqlalchemy/pool.py", line 1193, in _do_get
    return self._create_connection()
  File "/Users/jinxuanwu/github/systems-puzzle/venv/lib/python3.6/site-packages/sqlalchemy/pool.py", line 350, in _create_connection
    return _ConnectionRecord(self)
  File "/Users/jinxuanwu/github/systems-puzzle/venv/lib/python3.6/site-packages/sqlalchemy/pool.py", line 477, in __init__
    self.__connect(first_connect_check=True)
  File "/Users/jinxuanwu/github/systems-puzzle/venv/lib/python3.6/site-packages/sqlalchemy/pool.py", line 674, in __connect
    connection = pool._invoke_creator(self)
  File "/Users/jinxuanwu/github/systems-puzzle/venv/lib/python3.6/site-packages/sqlalchemy/engine/strategies.py", line 106, in connect
    return dialect.connect(*cargs, **cparams)
  File "/Users/jinxuanwu/github/systems-puzzle/venv/lib/python3.6/site-packages/sqlalchemy/engine/default.py", line 411, in connect
    return self.dbapi.connect(*cargs, **cparams)
  File "/Users/jinxuanwu/github/systems-puzzle/venv/lib/python3.6/site-packages/psycopg2/__init__.py", line 130, in connect
    conn = _connect(dsn, connection_factory=connection_factory, **kwasync)
sqlalchemy.exc.OperationalError: (psycopg2.OperationalError) fe_sendauth: no password supplied
 (Background on this error at: http://sqlalche.me/e/e3q8)
[pid: 71910|app: 0|req: 5/6] 127.0.0.1 () {42 vars in 855 bytes} [Mon Jun  4 23:15:50 2018] GET / => generated 291 bytes in 351 msecs (HTTP/1.1 500) 2 headers in 84 bytes (1 switches on core 3)
[2018-06-04 23:17:49,272] ERROR in app: Exception on / [GET]
Traceback (most recent call last):
  File "/Users/jinxuanwu/github/systems-puzzle/venv/lib/python3.6/site-packages/sqlalchemy/engine/base.py", line 2158, in _wrap_pool_connect
    return fn()
  File "/Users/jinxuanwu/github/systems-puzzle/venv/lib/python3.6/site-packages/sqlalchemy/pool.py", line 403, in connect
    return _ConnectionFairy._checkout(self)
  File "/Users/jinxuanwu/github/systems-puzzle/venv/lib/python3.6/site-packages/sqlalchemy/pool.py", line 791, in _checkout
    fairy = _ConnectionRecord.checkout(pool)
  File "/Users/jinxuanwu/github/systems-puzzle/venv/lib/python3.6/site-packages/sqlalchemy/pool.py", line 532, in checkout
    rec = pool._do_get()
  File "/Users/jinxuanwu/github/systems-puzzle/venv/lib/python3.6/site-packages/sqlalchemy/pool.py", line 1196, in _do_get
    self._dec_overflow()
  File "/Users/jinxuanwu/github/systems-puzzle/venv/lib/python3.6/site-packages/sqlalchemy/util/langhelpers.py", line 66, in __exit__
    compat.reraise(exc_type, exc_value, exc_tb)
  File "/Users/jinxuanwu/github/systems-puzzle/venv/lib/python3.6/site-packages/sqlalchemy/util/compat.py", line 187, in reraise
    raise value
  File "/Users/jinxuanwu/github/systems-puzzle/venv/lib/python3.6/site-packages/sqlalchemy/pool.py", line 1193, in _do_get
    return self._create_connection()
  File "/Users/jinxuanwu/github/systems-puzzle/venv/lib/python3.6/site-packages/sqlalchemy/pool.py", line 350, in _create_connection
    return _ConnectionRecord(self)
  File "/Users/jinxuanwu/github/systems-puzzle/venv/lib/python3.6/site-packages/sqlalchemy/pool.py", line 477, in __init__
    self.__connect(first_connect_check=True)
  File "/Users/jinxuanwu/github/systems-puzzle/venv/lib/python3.6/site-packages/sqlalchemy/pool.py", line 674, in __connect
    connection = pool._invoke_creator(self)
  File "/Users/jinxuanwu/github/systems-puzzle/venv/lib/python3.6/site-packages/sqlalchemy/engine/strategies.py", line 106, in connect
    return dialect.connect(*cargs, **cparams)
  File "/Users/jinxuanwu/github/systems-puzzle/venv/lib/python3.6/site-packages/sqlalchemy/engine/default.py", line 411, in connect
    return self.dbapi.connect(*cargs, **cparams)
  File "/Users/jinxuanwu/github/systems-puzzle/venv/lib/python3.6/site-packages/psycopg2/__init__.py", line 130, in connect
    conn = _connect(dsn, connection_factory=connection_factory, **kwasync)
psycopg2.OperationalError: fe_sendauth: no password supplied


The above exception was the direct cause of the following exception:

Traceback (most recent call last):
  File "/Users/jinxuanwu/github/systems-puzzle/venv/lib/python3.6/site-packages/flask/app.py", line 2292, in wsgi_app
    response = self.full_dispatch_request()
  File "/Users/jinxuanwu/github/systems-puzzle/venv/lib/python3.6/site-packages/flask/app.py", line 1815, in full_dispatch_request
    rv = self.handle_user_exception(e)
  File "/Users/jinxuanwu/github/systems-puzzle/venv/lib/python3.6/site-packages/flask/app.py", line 1718, in handle_user_exception
    reraise(exc_type, exc_value, tb)
  File "/Users/jinxuanwu/github/systems-puzzle/venv/lib/python3.6/site-packages/flask/_compat.py", line 35, in reraise
    raise value
  File "/Users/jinxuanwu/github/systems-puzzle/venv/lib/python3.6/site-packages/flask/app.py", line 1813, in full_dispatch_request
    rv = self.dispatch_request()
  File "/Users/jinxuanwu/github/systems-puzzle/venv/lib/python3.6/site-packages/flask/app.py", line 1799, in dispatch_request
    return self.view_functions[rule.endpoint](**req.view_args)
  File "/Users/jinxuanwu/github/systems-puzzle/app.py", line 20, in add_item
    current_items=Items.query.all()
  File "/Users/jinxuanwu/github/systems-puzzle/venv/lib/python3.6/site-packages/sqlalchemy/orm/query.py", line 2783, in all
    return list(self)
  File "/Users/jinxuanwu/github/systems-puzzle/venv/lib/python3.6/site-packages/sqlalchemy/orm/query.py", line 2935, in __iter__
    return self._execute_and_instances(context)
  File "/Users/jinxuanwu/github/systems-puzzle/venv/lib/python3.6/site-packages/sqlalchemy/orm/query.py", line 2956, in _execute_and_instances
    close_with_result=True)
  File "/Users/jinxuanwu/github/systems-puzzle/venv/lib/python3.6/site-packages/sqlalchemy/orm/query.py", line 2965, in _get_bind_args
    **kw
  File "/Users/jinxuanwu/github/systems-puzzle/venv/lib/python3.6/site-packages/sqlalchemy/orm/query.py", line 2947, in _connection_from_session
    conn = self.session.connection(**kw)
  File "/Users/jinxuanwu/github/systems-puzzle/venv/lib/python3.6/site-packages/sqlalchemy/orm/session.py", line 1035, in connection
    execution_options=execution_options)
  File "/Users/jinxuanwu/github/systems-puzzle/venv/lib/python3.6/site-packages/sqlalchemy/orm/session.py", line 1040, in _connection_for_bind
    engine, execution_options)
  File "/Users/jinxuanwu/github/systems-puzzle/venv/lib/python3.6/site-packages/sqlalchemy/orm/session.py", line 409, in _connection_for_bind
    conn = bind.contextual_connect()
  File "/Users/jinxuanwu/github/systems-puzzle/venv/lib/python3.6/site-packages/sqlalchemy/engine/base.py", line 2123, in contextual_connect
    self._wrap_pool_connect(self.pool.connect, None),
  File "/Users/jinxuanwu/github/systems-puzzle/venv/lib/python3.6/site-packages/sqlalchemy/engine/base.py", line 2162, in _wrap_pool_connect
    e, dialect, self)
  File "/Users/jinxuanwu/github/systems-puzzle/venv/lib/python3.6/site-packages/sqlalchemy/engine/base.py", line 1476, in _handle_dbapi_exception_noconnection
    exc_info
  File "/Users/jinxuanwu/github/systems-puzzle/venv/lib/python3.6/site-packages/sqlalchemy/util/compat.py", line 203, in raise_from_cause
    reraise(type(exception), exception, tb=exc_tb, cause=cause)
  File "/Users/jinxuanwu/github/systems-puzzle/venv/lib/python3.6/site-packages/sqlalchemy/util/compat.py", line 186, in reraise
    raise value.with_traceback(tb)
  File "/Users/jinxuanwu/github/systems-puzzle/venv/lib/python3.6/site-packages/sqlalchemy/engine/base.py", line 2158, in _wrap_pool_connect
    return fn()
  File "/Users/jinxuanwu/github/systems-puzzle/venv/lib/python3.6/site-packages/sqlalchemy/pool.py", line 403, in connect
    return _ConnectionFairy._checkout(self)
  File "/Users/jinxuanwu/github/systems-puzzle/venv/lib/python3.6/site-packages/sqlalchemy/pool.py", line 791, in _checkout
    fairy = _ConnectionRecord.checkout(pool)
  File "/Users/jinxuanwu/github/systems-puzzle/venv/lib/python3.6/site-packages/sqlalchemy/pool.py", line 532, in checkout
    rec = pool._do_get()
  File "/Users/jinxuanwu/github/systems-puzzle/venv/lib/python3.6/site-packages/sqlalchemy/pool.py", line 1196, in _do_get
    self._dec_overflow()
  File "/Users/jinxuanwu/github/systems-puzzle/venv/lib/python3.6/site-packages/sqlalchemy/util/langhelpers.py", line 66, in __exit__
    compat.reraise(exc_type, exc_value, exc_tb)
  File "/Users/jinxuanwu/github/systems-puzzle/venv/lib/python3.6/site-packages/sqlalchemy/util/compat.py", line 187, in reraise
    raise value
  File "/Users/jinxuanwu/github/systems-puzzle/venv/lib/python3.6/site-packages/sqlalchemy/pool.py", line 1193, in _do_get
    return self._create_connection()
  File "/Users/jinxuanwu/github/systems-puzzle/venv/lib/python3.6/site-packages/sqlalchemy/pool.py", line 350, in _create_connection
    return _ConnectionRecord(self)
  File "/Users/jinxuanwu/github/systems-puzzle/venv/lib/python3.6/site-packages/sqlalchemy/pool.py", line 477, in __init__
    self.__connect(first_connect_check=True)
  File "/Users/jinxuanwu/github/systems-puzzle/venv/lib/python3.6/site-packages/sqlalchemy/pool.py", line 674, in __connect
    connection = pool._invoke_creator(self)
  File "/Users/jinxuanwu/github/systems-puzzle/venv/lib/python3.6/site-packages/sqlalchemy/engine/strategies.py", line 106, in connect
    return dialect.connect(*cargs, **cparams)
  File "/Users/jinxuanwu/github/systems-puzzle/venv/lib/python3.6/site-packages/sqlalchemy/engine/default.py", line 411, in connect
    return self.dbapi.connect(*cargs, **cparams)
  File "/Users/jinxuanwu/github/systems-puzzle/venv/lib/python3.6/site-packages/psycopg2/__init__.py", line 130, in connect
    conn = _connect(dsn, connection_factory=connection_factory, **kwasync)
sqlalchemy.exc.OperationalError: (psycopg2.OperationalError) fe_sendauth: no password supplied
 (Background on this error at: http://sqlalche.me/e/e3q8)
[pid: 71910|app: 0|req: 6/7] 127.0.0.1 () {42 vars in 855 bytes} [Mon Jun  4 23:17:49 2018] GET / => generated 291 bytes in 87 msecs (HTTP/1.1 500) 2 headers in 84 bytes (1 switches on core 2)
[2018-06-04 23:27:27,333] ERROR in app: Exception on / [GET]
Traceback (most recent call last):
  File "/Users/jinxuanwu/github/systems-puzzle/venv/lib/python3.6/site-packages/sqlalchemy/engine/base.py", line 1193, in _execute_context
    context)
  File "/Users/jinxuanwu/github/systems-puzzle/venv/lib/python3.6/site-packages/sqlalchemy/engine/default.py", line 508, in do_execute
    cursor.execute(statement, parameters)
psycopg2.OperationalError: terminating connection due to administrator command
server closed the connection unexpectedly
	This probably means the server terminated abnormally
	before or while processing the request.


The above exception was the direct cause of the following exception:

Traceback (most recent call last):
  File "/Users/jinxuanwu/github/systems-puzzle/venv/lib/python3.6/site-packages/flask/app.py", line 2292, in wsgi_app
    response = self.full_dispatch_request()
  File "/Users/jinxuanwu/github/systems-puzzle/venv/lib/python3.6/site-packages/flask/app.py", line 1815, in full_dispatch_request
    rv = self.handle_user_exception(e)
  File "/Users/jinxuanwu/github/systems-puzzle/venv/lib/python3.6/site-packages/flask/app.py", line 1718, in handle_user_exception
    reraise(exc_type, exc_value, tb)
  File "/Users/jinxuanwu/github/systems-puzzle/venv/lib/python3.6/site-packages/flask/_compat.py", line 35, in reraise
    raise value
  File "/Users/jinxuanwu/github/systems-puzzle/venv/lib/python3.6/site-packages/flask/app.py", line 1813, in full_dispatch_request
    rv = self.dispatch_request()
  File "/Users/jinxuanwu/github/systems-puzzle/venv/lib/python3.6/site-packages/flask/app.py", line 1799, in dispatch_request
    return self.view_functions[rule.endpoint](**req.view_args)
  File "/Users/jinxuanwu/github/systems-puzzle/app.py", line 20, in add_item
    current_items=Items.query.all()
  File "/Users/jinxuanwu/github/systems-puzzle/venv/lib/python3.6/site-packages/sqlalchemy/orm/query.py", line 2783, in all
    return list(self)
  File "/Users/jinxuanwu/github/systems-puzzle/venv/lib/python3.6/site-packages/sqlalchemy/orm/query.py", line 2935, in __iter__
    return self._execute_and_instances(context)
  File "/Users/jinxuanwu/github/systems-puzzle/venv/lib/python3.6/site-packages/sqlalchemy/orm/query.py", line 2958, in _execute_and_instances
    result = conn.execute(querycontext.statement, self._params)
  File "/Users/jinxuanwu/github/systems-puzzle/venv/lib/python3.6/site-packages/sqlalchemy/engine/base.py", line 948, in execute
    return meth(self, multiparams, params)
  File "/Users/jinxuanwu/github/systems-puzzle/venv/lib/python3.6/site-packages/sqlalchemy/sql/elements.py", line 269, in _execute_on_connection
    return connection._execute_clauseelement(self, multiparams, params)
  File "/Users/jinxuanwu/github/systems-puzzle/venv/lib/python3.6/site-packages/sqlalchemy/engine/base.py", line 1060, in _execute_clauseelement
    compiled_sql, distilled_params
  File "/Users/jinxuanwu/github/systems-puzzle/venv/lib/python3.6/site-packages/sqlalchemy/engine/base.py", line 1200, in _execute_context
    context)
  File "/Users/jinxuanwu/github/systems-puzzle/venv/lib/python3.6/site-packages/sqlalchemy/engine/base.py", line 1413, in _handle_dbapi_exception
    exc_info
  File "/Users/jinxuanwu/github/systems-puzzle/venv/lib/python3.6/site-packages/sqlalchemy/util/compat.py", line 203, in raise_from_cause
    reraise(type(exception), exception, tb=exc_tb, cause=cause)
  File "/Users/jinxuanwu/github/systems-puzzle/venv/lib/python3.6/site-packages/sqlalchemy/util/compat.py", line 186, in reraise
    raise value.with_traceback(tb)
  File "/Users/jinxuanwu/github/systems-puzzle/venv/lib/python3.6/site-packages/sqlalchemy/engine/base.py", line 1193, in _execute_context
    context)
  File "/Users/jinxuanwu/github/systems-puzzle/venv/lib/python3.6/site-packages/sqlalchemy/engine/default.py", line 508, in do_execute
    cursor.execute(statement, parameters)
sqlalchemy.exc.OperationalError: (psycopg2.OperationalError) terminating connection due to administrator command
server closed the connection unexpectedly
	This probably means the server terminated abnormally
	before or while processing the request.
 [SQL: 'SELECT items.id AS items_id, items.name AS items_name, items.quantity AS items_quantity, items.description AS items_description, items.date_added AS items_date_added \nFROM items'] (Background on this error at: http://sqlalche.me/e/e3q8)
[pid: 71909|app: 0|req: 2/8] 127.0.0.1 () {44 vars in 886 bytes} [Mon Jun  4 23:27:27 2018] GET / => generated 291 bytes in 342 msecs (HTTP/1.1 500) 2 headers in 84 bytes (1 switches on core 3)
[2018-06-04 23:29:37,483] ERROR in app: Exception on / [GET]
Traceback (most recent call last):
  File "/Users/jinxuanwu/github/systems-puzzle/venv/lib/python3.6/site-packages/sqlalchemy/engine/base.py", line 2158, in _wrap_pool_connect
    return fn()
  File "/Users/jinxuanwu/github/systems-puzzle/venv/lib/python3.6/site-packages/sqlalchemy/pool.py", line 403, in connect
    return _ConnectionFairy._checkout(self)
  File "/Users/jinxuanwu/github/systems-puzzle/venv/lib/python3.6/site-packages/sqlalchemy/pool.py", line 791, in _checkout
    fairy = _ConnectionRecord.checkout(pool)
  File "/Users/jinxuanwu/github/systems-puzzle/venv/lib/python3.6/site-packages/sqlalchemy/pool.py", line 537, in checkout
    rec._checkin_failed(err)
  File "/Users/jinxuanwu/github/systems-puzzle/venv/lib/python3.6/site-packages/sqlalchemy/util/langhelpers.py", line 66, in __exit__
    compat.reraise(exc_type, exc_value, exc_tb)
  File "/Users/jinxuanwu/github/systems-puzzle/venv/lib/python3.6/site-packages/sqlalchemy/util/compat.py", line 187, in reraise
    raise value
  File "/Users/jinxuanwu/github/systems-puzzle/venv/lib/python3.6/site-packages/sqlalchemy/pool.py", line 534, in checkout
    dbapi_connection = rec.get_connection()
  File "/Users/jinxuanwu/github/systems-puzzle/venv/lib/python3.6/site-packages/sqlalchemy/pool.py", line 630, in get_connection
    self.__connect()
  File "/Users/jinxuanwu/github/systems-puzzle/venv/lib/python3.6/site-packages/sqlalchemy/pool.py", line 674, in __connect
    connection = pool._invoke_creator(self)
  File "/Users/jinxuanwu/github/systems-puzzle/venv/lib/python3.6/site-packages/sqlalchemy/engine/strategies.py", line 106, in connect
    return dialect.connect(*cargs, **cparams)
  File "/Users/jinxuanwu/github/systems-puzzle/venv/lib/python3.6/site-packages/sqlalchemy/engine/default.py", line 411, in connect
    return self.dbapi.connect(*cargs, **cparams)
  File "/Users/jinxuanwu/github/systems-puzzle/venv/lib/python3.6/site-packages/psycopg2/__init__.py", line 130, in connect
    conn = _connect(dsn, connection_factory=connection_factory, **kwasync)
psycopg2.OperationalError: fe_sendauth: no password supplied


The above exception was the direct cause of the following exception:

Traceback (most recent call last):
  File "/Users/jinxuanwu/github/systems-puzzle/venv/lib/python3.6/site-packages/flask/app.py", line 2292, in wsgi_app
    response = self.full_dispatch_request()
  File "/Users/jinxuanwu/github/systems-puzzle/venv/lib/python3.6/site-packages/flask/app.py", line 1815, in full_dispatch_request
    rv = self.handle_user_exception(e)
  File "/Users/jinxuanwu/github/systems-puzzle/venv/lib/python3.6/site-packages/flask/app.py", line 1718, in handle_user_exception
    reraise(exc_type, exc_value, tb)
  File "/Users/jinxuanwu/github/systems-puzzle/venv/lib/python3.6/site-packages/flask/_compat.py", line 35, in reraise
    raise value
  File "/Users/jinxuanwu/github/systems-puzzle/venv/lib/python3.6/site-packages/flask/app.py", line 1813, in full_dispatch_request
    rv = self.dispatch_request()
  File "/Users/jinxuanwu/github/systems-puzzle/venv/lib/python3.6/site-packages/flask/app.py", line 1799, in dispatch_request
    return self.view_functions[rule.endpoint](**req.view_args)
  File "/Users/jinxuanwu/github/systems-puzzle/app.py", line 20, in add_item
    current_items=Items.query.all()
  File "/Users/jinxuanwu/github/systems-puzzle/venv/lib/python3.6/site-packages/sqlalchemy/orm/query.py", line 2783, in all
    return list(self)
  File "/Users/jinxuanwu/github/systems-puzzle/venv/lib/python3.6/site-packages/sqlalchemy/orm/query.py", line 2935, in __iter__
    return self._execute_and_instances(context)
  File "/Users/jinxuanwu/github/systems-puzzle/venv/lib/python3.6/site-packages/sqlalchemy/orm/query.py", line 2956, in _execute_and_instances
    close_with_result=True)
  File "/Users/jinxuanwu/github/systems-puzzle/venv/lib/python3.6/site-packages/sqlalchemy/orm/query.py", line 2965, in _get_bind_args
    **kw
  File "/Users/jinxuanwu/github/systems-puzzle/venv/lib/python3.6/site-packages/sqlalchemy/orm/query.py", line 2947, in _connection_from_session
    conn = self.session.connection(**kw)
  File "/Users/jinxuanwu/github/systems-puzzle/venv/lib/python3.6/site-packages/sqlalchemy/orm/session.py", line 1035, in connection
    execution_options=execution_options)
  File "/Users/jinxuanwu/github/systems-puzzle/venv/lib/python3.6/site-packages/sqlalchemy/orm/session.py", line 1040, in _connection_for_bind
    engine, execution_options)
  File "/Users/jinxuanwu/github/systems-puzzle/venv/lib/python3.6/site-packages/sqlalchemy/orm/session.py", line 409, in _connection_for_bind
    conn = bind.contextual_connect()
  File "/Users/jinxuanwu/github/systems-puzzle/venv/lib/python3.6/site-packages/sqlalchemy/engine/base.py", line 2123, in contextual_connect
    self._wrap_pool_connect(self.pool.connect, None),
  File "/Users/jinxuanwu/github/systems-puzzle/venv/lib/python3.6/site-packages/sqlalchemy/engine/base.py", line 2162, in _wrap_pool_connect
    e, dialect, self)
  File "/Users/jinxuanwu/github/systems-puzzle/venv/lib/python3.6/site-packages/sqlalchemy/engine/base.py", line 1476, in _handle_dbapi_exception_noconnection
    exc_info
  File "/Users/jinxuanwu/github/systems-puzzle/venv/lib/python3.6/site-packages/sqlalchemy/util/compat.py", line 203, in raise_from_cause
    reraise(type(exception), exception, tb=exc_tb, cause=cause)
  File "/Users/jinxuanwu/github/systems-puzzle/venv/lib/python3.6/site-packages/sqlalchemy/util/compat.py", line 186, in reraise
    raise value.with_traceback(tb)
  File "/Users/jinxuanwu/github/systems-puzzle/venv/lib/python3.6/site-packages/sqlalchemy/engine/base.py", line 2158, in _wrap_pool_connect
    return fn()
  File "/Users/jinxuanwu/github/systems-puzzle/venv/lib/python3.6/site-packages/sqlalchemy/pool.py", line 403, in connect
    return _ConnectionFairy._checkout(self)
  File "/Users/jinxuanwu/github/systems-puzzle/venv/lib/python3.6/site-packages/sqlalchemy/pool.py", line 791, in _checkout
    fairy = _ConnectionRecord.checkout(pool)
  File "/Users/jinxuanwu/github/systems-puzzle/venv/lib/python3.6/site-packages/sqlalchemy/pool.py", line 537, in checkout
    rec._checkin_failed(err)
  File "/Users/jinxuanwu/github/systems-puzzle/venv/lib/python3.6/site-packages/sqlalchemy/util/langhelpers.py", line 66, in __exit__
    compat.reraise(exc_type, exc_value, exc_tb)
  File "/Users/jinxuanwu/github/systems-puzzle/venv/lib/python3.6/site-packages/sqlalchemy/util/compat.py", line 187, in reraise
    raise value
  File "/Users/jinxuanwu/github/systems-puzzle/venv/lib/python3.6/site-packages/sqlalchemy/pool.py", line 534, in checkout
    dbapi_connection = rec.get_connection()
  File "/Users/jinxuanwu/github/systems-puzzle/venv/lib/python3.6/site-packages/sqlalchemy/pool.py", line 630, in get_connection
    self.__connect()
  File "/Users/jinxuanwu/github/systems-puzzle/venv/lib/python3.6/site-packages/sqlalchemy/pool.py", line 674, in __connect
    connection = pool._invoke_creator(self)
  File "/Users/jinxuanwu/github/systems-puzzle/venv/lib/python3.6/site-packages/sqlalchemy/engine/strategies.py", line 106, in connect
    return dialect.connect(*cargs, **cparams)
  File "/Users/jinxuanwu/github/systems-puzzle/venv/lib/python3.6/site-packages/sqlalchemy/engine/default.py", line 411, in connect
    return self.dbapi.connect(*cargs, **cparams)
  File "/Users/jinxuanwu/github/systems-puzzle/venv/lib/python3.6/site-packages/psycopg2/__init__.py", line 130, in connect
    conn = _connect(dsn, connection_factory=connection_factory, **kwasync)
sqlalchemy.exc.OperationalError: (psycopg2.OperationalError) fe_sendauth: no password supplied
 (Background on this error at: http://sqlalche.me/e/e3q8)
[pid: 71909|app: 0|req: 3/9] 127.0.0.1 () {44 vars in 886 bytes} [Mon Jun  4 23:29:37 2018] GET / => generated 291 bytes in 258 msecs (HTTP/1.1 500) 2 headers in 84 bytes (1 switches on core 0)
[2018-06-04 23:30:31,287] ERROR in app: Exception on / [GET]
Traceback (most recent call last):
  File "/Users/jinxuanwu/github/systems-puzzle/venv/lib/python3.6/site-packages/sqlalchemy/engine/base.py", line 2158, in _wrap_pool_connect
    return fn()
  File "/Users/jinxuanwu/github/systems-puzzle/venv/lib/python3.6/site-packages/sqlalchemy/pool.py", line 403, in connect
    return _ConnectionFairy._checkout(self)
  File "/Users/jinxuanwu/github/systems-puzzle/venv/lib/python3.6/site-packages/sqlalchemy/pool.py", line 791, in _checkout
    fairy = _ConnectionRecord.checkout(pool)
  File "/Users/jinxuanwu/github/systems-puzzle/venv/lib/python3.6/site-packages/sqlalchemy/pool.py", line 532, in checkout
    rec = pool._do_get()
  File "/Users/jinxuanwu/github/systems-puzzle/venv/lib/python3.6/site-packages/sqlalchemy/pool.py", line 1196, in _do_get
    self._dec_overflow()
  File "/Users/jinxuanwu/github/systems-puzzle/venv/lib/python3.6/site-packages/sqlalchemy/util/langhelpers.py", line 66, in __exit__
    compat.reraise(exc_type, exc_value, exc_tb)
  File "/Users/jinxuanwu/github/systems-puzzle/venv/lib/python3.6/site-packages/sqlalchemy/util/compat.py", line 187, in reraise
    raise value
  File "/Users/jinxuanwu/github/systems-puzzle/venv/lib/python3.6/site-packages/sqlalchemy/pool.py", line 1193, in _do_get
    return self._create_connection()
  File "/Users/jinxuanwu/github/systems-puzzle/venv/lib/python3.6/site-packages/sqlalchemy/pool.py", line 350, in _create_connection
    return _ConnectionRecord(self)
  File "/Users/jinxuanwu/github/systems-puzzle/venv/lib/python3.6/site-packages/sqlalchemy/pool.py", line 477, in __init__
    self.__connect(first_connect_check=True)
  File "/Users/jinxuanwu/github/systems-puzzle/venv/lib/python3.6/site-packages/sqlalchemy/pool.py", line 674, in __connect
    connection = pool._invoke_creator(self)
  File "/Users/jinxuanwu/github/systems-puzzle/venv/lib/python3.6/site-packages/sqlalchemy/engine/strategies.py", line 106, in connect
    return dialect.connect(*cargs, **cparams)
  File "/Users/jinxuanwu/github/systems-puzzle/venv/lib/python3.6/site-packages/sqlalchemy/engine/default.py", line 411, in connect
    return self.dbapi.connect(*cargs, **cparams)
  File "/Users/jinxuanwu/github/systems-puzzle/venv/lib/python3.6/site-packages/psycopg2/__init__.py", line 130, in connect
    conn = _connect(dsn, connection_factory=connection_factory, **kwasync)
psycopg2.OperationalError: fe_sendauth: no password supplied


The above exception was the direct cause of the following exception:

Traceback (most recent call last):
  File "/Users/jinxuanwu/github/systems-puzzle/venv/lib/python3.6/site-packages/flask/app.py", line 2292, in wsgi_app
    response = self.full_dispatch_request()
  File "/Users/jinxuanwu/github/systems-puzzle/venv/lib/python3.6/site-packages/flask/app.py", line 1815, in full_dispatch_request
    rv = self.handle_user_exception(e)
  File "/Users/jinxuanwu/github/systems-puzzle/venv/lib/python3.6/site-packages/flask/app.py", line 1718, in handle_user_exception
    reraise(exc_type, exc_value, tb)
  File "/Users/jinxuanwu/github/systems-puzzle/venv/lib/python3.6/site-packages/flask/_compat.py", line 35, in reraise
    raise value
  File "/Users/jinxuanwu/github/systems-puzzle/venv/lib/python3.6/site-packages/flask/app.py", line 1813, in full_dispatch_request
    rv = self.dispatch_request()
  File "/Users/jinxuanwu/github/systems-puzzle/venv/lib/python3.6/site-packages/flask/app.py", line 1799, in dispatch_request
    return self.view_functions[rule.endpoint](**req.view_args)
  File "/Users/jinxuanwu/github/systems-puzzle/app.py", line 20, in add_item
    current_items=Items.query.all()
  File "/Users/jinxuanwu/github/systems-puzzle/venv/lib/python3.6/site-packages/sqlalchemy/orm/query.py", line 2783, in all
    return list(self)
  File "/Users/jinxuanwu/github/systems-puzzle/venv/lib/python3.6/site-packages/sqlalchemy/orm/query.py", line 2935, in __iter__
    return self._execute_and_instances(context)
  File "/Users/jinxuanwu/github/systems-puzzle/venv/lib/python3.6/site-packages/sqlalchemy/orm/query.py", line 2956, in _execute_and_instances
    close_with_result=True)
  File "/Users/jinxuanwu/github/systems-puzzle/venv/lib/python3.6/site-packages/sqlalchemy/orm/query.py", line 2965, in _get_bind_args
    **kw
  File "/Users/jinxuanwu/github/systems-puzzle/venv/lib/python3.6/site-packages/sqlalchemy/orm/query.py", line 2947, in _connection_from_session
    conn = self.session.connection(**kw)
  File "/Users/jinxuanwu/github/systems-puzzle/venv/lib/python3.6/site-packages/sqlalchemy/orm/session.py", line 1035, in connection
    execution_options=execution_options)
  File "/Users/jinxuanwu/github/systems-puzzle/venv/lib/python3.6/site-packages/sqlalchemy/orm/session.py", line 1040, in _connection_for_bind
    engine, execution_options)
  File "/Users/jinxuanwu/github/systems-puzzle/venv/lib/python3.6/site-packages/sqlalchemy/orm/session.py", line 409, in _connection_for_bind
    conn = bind.contextual_connect()
  File "/Users/jinxuanwu/github/systems-puzzle/venv/lib/python3.6/site-packages/sqlalchemy/engine/base.py", line 2123, in contextual_connect
    self._wrap_pool_connect(self.pool.connect, None),
  File "/Users/jinxuanwu/github/systems-puzzle/venv/lib/python3.6/site-packages/sqlalchemy/engine/base.py", line 2162, in _wrap_pool_connect
    e, dialect, self)
  File "/Users/jinxuanwu/github/systems-puzzle/venv/lib/python3.6/site-packages/sqlalchemy/engine/base.py", line 1476, in _handle_dbapi_exception_noconnection
    exc_info
  File "/Users/jinxuanwu/github/systems-puzzle/venv/lib/python3.6/site-packages/sqlalchemy/util/compat.py", line 203, in raise_from_cause
    reraise(type(exception), exception, tb=exc_tb, cause=cause)
  File "/Users/jinxuanwu/github/systems-puzzle/venv/lib/python3.6/site-packages/sqlalchemy/util/compat.py", line 186, in reraise
    raise value.with_traceback(tb)
  File "/Users/jinxuanwu/github/systems-puzzle/venv/lib/python3.6/site-packages/sqlalchemy/engine/base.py", line 2158, in _wrap_pool_connect
    return fn()
  File "/Users/jinxuanwu/github/systems-puzzle/venv/lib/python3.6/site-packages/sqlalchemy/pool.py", line 403, in connect
    return _ConnectionFairy._checkout(self)
  File "/Users/jinxuanwu/github/systems-puzzle/venv/lib/python3.6/site-packages/sqlalchemy/pool.py", line 791, in _checkout
    fairy = _ConnectionRecord.checkout(pool)
  File "/Users/jinxuanwu/github/systems-puzzle/venv/lib/python3.6/site-packages/sqlalchemy/pool.py", line 532, in checkout
    rec = pool._do_get()
  File "/Users/jinxuanwu/github/systems-puzzle/venv/lib/python3.6/site-packages/sqlalchemy/pool.py", line 1196, in _do_get
    self._dec_overflow()
  File "/Users/jinxuanwu/github/systems-puzzle/venv/lib/python3.6/site-packages/sqlalchemy/util/langhelpers.py", line 66, in __exit__
    compat.reraise(exc_type, exc_value, exc_tb)
  File "/Users/jinxuanwu/github/systems-puzzle/venv/lib/python3.6/site-packages/sqlalchemy/util/compat.py", line 187, in reraise
    raise value
  File "/Users/jinxuanwu/github/systems-puzzle/venv/lib/python3.6/site-packages/sqlalchemy/pool.py", line 1193, in _do_get
    return self._create_connection()
  File "/Users/jinxuanwu/github/systems-puzzle/venv/lib/python3.6/site-packages/sqlalchemy/pool.py", line 350, in _create_connection
    return _ConnectionRecord(self)
  File "/Users/jinxuanwu/github/systems-puzzle/venv/lib/python3.6/site-packages/sqlalchemy/pool.py", line 477, in __init__
    self.__connect(first_connect_check=True)
  File "/Users/jinxuanwu/github/systems-puzzle/venv/lib/python3.6/site-packages/sqlalchemy/pool.py", line 674, in __connect
    connection = pool._invoke_creator(self)
  File "/Users/jinxuanwu/github/systems-puzzle/venv/lib/python3.6/site-packages/sqlalchemy/engine/strategies.py", line 106, in connect
    return dialect.connect(*cargs, **cparams)
  File "/Users/jinxuanwu/github/systems-puzzle/venv/lib/python3.6/site-packages/sqlalchemy/engine/default.py", line 411, in connect
    return self.dbapi.connect(*cargs, **cparams)
  File "/Users/jinxuanwu/github/systems-puzzle/venv/lib/python3.6/site-packages/psycopg2/__init__.py", line 130, in connect
    conn = _connect(dsn, connection_factory=connection_factory, **kwasync)
sqlalchemy.exc.OperationalError: (psycopg2.OperationalError) fe_sendauth: no password supplied
 (Background on this error at: http://sqlalche.me/e/e3q8)
[pid: 71907|app: 0|req: 1/10] 127.0.0.1 () {44 vars in 886 bytes} [Mon Jun  4 23:30:30 2018] GET / => generated 291 bytes in 384 msecs (HTTP/1.1 500) 2 headers in 84 bytes (1 switches on core 2)
[2018-06-04 23:49:50,183] ERROR in app: Exception on / [GET]
Traceback (most recent call last):
  File "/Users/jinxuanwu/github/systems-puzzle/venv/lib/python3.6/site-packages/sqlalchemy/engine/base.py", line 2158, in _wrap_pool_connect
    return fn()
  File "/Users/jinxuanwu/github/systems-puzzle/venv/lib/python3.6/site-packages/sqlalchemy/pool.py", line 403, in connect
    return _ConnectionFairy._checkout(self)
  File "/Users/jinxuanwu/github/systems-puzzle/venv/lib/python3.6/site-packages/sqlalchemy/pool.py", line 791, in _checkout
    fairy = _ConnectionRecord.checkout(pool)
  File "/Users/jinxuanwu/github/systems-puzzle/venv/lib/python3.6/site-packages/sqlalchemy/pool.py", line 532, in checkout
    rec = pool._do_get()
  File "/Users/jinxuanwu/github/systems-puzzle/venv/lib/python3.6/site-packages/sqlalchemy/pool.py", line 1196, in _do_get
    self._dec_overflow()
  File "/Users/jinxuanwu/github/systems-puzzle/venv/lib/python3.6/site-packages/sqlalchemy/util/langhelpers.py", line 66, in __exit__
    compat.reraise(exc_type, exc_value, exc_tb)
  File "/Users/jinxuanwu/github/systems-puzzle/venv/lib/python3.6/site-packages/sqlalchemy/util/compat.py", line 187, in reraise
    raise value
  File "/Users/jinxuanwu/github/systems-puzzle/venv/lib/python3.6/site-packages/sqlalchemy/pool.py", line 1193, in _do_get
    return self._create_connection()
  File "/Users/jinxuanwu/github/systems-puzzle/venv/lib/python3.6/site-packages/sqlalchemy/pool.py", line 350, in _create_connection
    return _ConnectionRecord(self)
  File "/Users/jinxuanwu/github/systems-puzzle/venv/lib/python3.6/site-packages/sqlalchemy/pool.py", line 477, in __init__
    self.__connect(first_connect_check=True)
  File "/Users/jinxuanwu/github/systems-puzzle/venv/lib/python3.6/site-packages/sqlalchemy/pool.py", line 674, in __connect
    connection = pool._invoke_creator(self)
  File "/Users/jinxuanwu/github/systems-puzzle/venv/lib/python3.6/site-packages/sqlalchemy/engine/strategies.py", line 106, in connect
    return dialect.connect(*cargs, **cparams)
  File "/Users/jinxuanwu/github/systems-puzzle/venv/lib/python3.6/site-packages/sqlalchemy/engine/default.py", line 411, in connect
    return self.dbapi.connect(*cargs, **cparams)
  File "/Users/jinxuanwu/github/systems-puzzle/venv/lib/python3.6/site-packages/psycopg2/__init__.py", line 130, in connect
    conn = _connect(dsn, connection_factory=connection_factory, **kwasync)
psycopg2.OperationalError: fe_sendauth: no password supplied


The above exception was the direct cause of the following exception:

Traceback (most recent call last):
  File "/Users/jinxuanwu/github/systems-puzzle/venv/lib/python3.6/site-packages/flask/app.py", line 2292, in wsgi_app
    response = self.full_dispatch_request()
  File "/Users/jinxuanwu/github/systems-puzzle/venv/lib/python3.6/site-packages/flask/app.py", line 1815, in full_dispatch_request
    rv = self.handle_user_exception(e)
  File "/Users/jinxuanwu/github/systems-puzzle/venv/lib/python3.6/site-packages/flask/app.py", line 1718, in handle_user_exception
    reraise(exc_type, exc_value, tb)
  File "/Users/jinxuanwu/github/systems-puzzle/venv/lib/python3.6/site-packages/flask/_compat.py", line 35, in reraise
    raise value
  File "/Users/jinxuanwu/github/systems-puzzle/venv/lib/python3.6/site-packages/flask/app.py", line 1813, in full_dispatch_request
    rv = self.dispatch_request()
  File "/Users/jinxuanwu/github/systems-puzzle/venv/lib/python3.6/site-packages/flask/app.py", line 1799, in dispatch_request
    return self.view_functions[rule.endpoint](**req.view_args)
  File "/Users/jinxuanwu/github/systems-puzzle/app.py", line 20, in add_item
    current_items=Items.query.all()
  File "/Users/jinxuanwu/github/systems-puzzle/venv/lib/python3.6/site-packages/sqlalchemy/orm/query.py", line 2783, in all
    return list(self)
  File "/Users/jinxuanwu/github/systems-puzzle/venv/lib/python3.6/site-packages/sqlalchemy/orm/query.py", line 2935, in __iter__
    return self._execute_and_instances(context)
  File "/Users/jinxuanwu/github/systems-puzzle/venv/lib/python3.6/site-packages/sqlalchemy/orm/query.py", line 2956, in _execute_and_instances
    close_with_result=True)
  File "/Users/jinxuanwu/github/systems-puzzle/venv/lib/python3.6/site-packages/sqlalchemy/orm/query.py", line 2965, in _get_bind_args
    **kw
  File "/Users/jinxuanwu/github/systems-puzzle/venv/lib/python3.6/site-packages/sqlalchemy/orm/query.py", line 2947, in _connection_from_session
    conn = self.session.connection(**kw)
  File "/Users/jinxuanwu/github/systems-puzzle/venv/lib/python3.6/site-packages/sqlalchemy/orm/session.py", line 1035, in connection
    execution_options=execution_options)
  File "/Users/jinxuanwu/github/systems-puzzle/venv/lib/python3.6/site-packages/sqlalchemy/orm/session.py", line 1040, in _connection_for_bind
    engine, execution_options)
  File "/Users/jinxuanwu/github/systems-puzzle/venv/lib/python3.6/site-packages/sqlalchemy/orm/session.py", line 409, in _connection_for_bind
    conn = bind.contextual_connect()
  File "/Users/jinxuanwu/github/systems-puzzle/venv/lib/python3.6/site-packages/sqlalchemy/engine/base.py", line 2123, in contextual_connect
    self._wrap_pool_connect(self.pool.connect, None),
  File "/Users/jinxuanwu/github/systems-puzzle/venv/lib/python3.6/site-packages/sqlalchemy/engine/base.py", line 2162, in _wrap_pool_connect
    e, dialect, self)
  File "/Users/jinxuanwu/github/systems-puzzle/venv/lib/python3.6/site-packages/sqlalchemy/engine/base.py", line 1476, in _handle_dbapi_exception_noconnection
    exc_info
  File "/Users/jinxuanwu/github/systems-puzzle/venv/lib/python3.6/site-packages/sqlalchemy/util/compat.py", line 203, in raise_from_cause
    reraise(type(exception), exception, tb=exc_tb, cause=cause)
  File "/Users/jinxuanwu/github/systems-puzzle/venv/lib/python3.6/site-packages/sqlalchemy/util/compat.py", line 186, in reraise
    raise value.with_traceback(tb)
  File "/Users/jinxuanwu/github/systems-puzzle/venv/lib/python3.6/site-packages/sqlalchemy/engine/base.py", line 2158, in _wrap_pool_connect
    return fn()
  File "/Users/jinxuanwu/github/systems-puzzle/venv/lib/python3.6/site-packages/sqlalchemy/pool.py", line 403, in connect
    return _ConnectionFairy._checkout(self)
  File "/Users/jinxuanwu/github/systems-puzzle/venv/lib/python3.6/site-packages/sqlalchemy/pool.py", line 791, in _checkout
    fairy = _ConnectionRecord.checkout(pool)
  File "/Users/jinxuanwu/github/systems-puzzle/venv/lib/python3.6/site-packages/sqlalchemy/pool.py", line 532, in checkout
    rec = pool._do_get()
  File "/Users/jinxuanwu/github/systems-puzzle/venv/lib/python3.6/site-packages/sqlalchemy/pool.py", line 1196, in _do_get
    self._dec_overflow()
  File "/Users/jinxuanwu/github/systems-puzzle/venv/lib/python3.6/site-packages/sqlalchemy/util/langhelpers.py", line 66, in __exit__
    compat.reraise(exc_type, exc_value, exc_tb)
  File "/Users/jinxuanwu/github/systems-puzzle/venv/lib/python3.6/site-packages/sqlalchemy/util/compat.py", line 187, in reraise
    raise value
  File "/Users/jinxuanwu/github/systems-puzzle/venv/lib/python3.6/site-packages/sqlalchemy/pool.py", line 1193, in _do_get
    return self._create_connection()
  File "/Users/jinxuanwu/github/systems-puzzle/venv/lib/python3.6/site-packages/sqlalchemy/pool.py", line 350, in _create_connection
    return _ConnectionRecord(self)
  File "/Users/jinxuanwu/github/systems-puzzle/venv/lib/python3.6/site-packages/sqlalchemy/pool.py", line 477, in __init__
    self.__connect(first_connect_check=True)
  File "/Users/jinxuanwu/github/systems-puzzle/venv/lib/python3.6/site-packages/sqlalchemy/pool.py", line 674, in __connect
    connection = pool._invoke_creator(self)
  File "/Users/jinxuanwu/github/systems-puzzle/venv/lib/python3.6/site-packages/sqlalchemy/engine/strategies.py", line 106, in connect
    return dialect.connect(*cargs, **cparams)
  File "/Users/jinxuanwu/github/systems-puzzle/venv/lib/python3.6/site-packages/sqlalchemy/engine/default.py", line 411, in connect
    return self.dbapi.connect(*cargs, **cparams)
  File "/Users/jinxuanwu/github/systems-puzzle/venv/lib/python3.6/site-packages/psycopg2/__init__.py", line 130, in connect
    conn = _connect(dsn, connection_factory=connection_factory, **kwasync)
sqlalchemy.exc.OperationalError: (psycopg2.OperationalError) fe_sendauth: no password supplied
 (Background on this error at: http://sqlalche.me/e/e3q8)
[pid: 71908|app: 0|req: 1/11] 127.0.0.1 () {44 vars in 886 bytes} [Mon Jun  4 23:49:49 2018] GET / => generated 291 bytes in 600 msecs (HTTP/1.1 500) 2 headers in 84 bytes (1 switches on core 0)
